Workbook

Sheet Goal
A1: CHIPOTLE MEXICAN GRILL (NYSE: CMG)
A2: Driver-Based 3-Statement Operating Model & FP&A Case Study
A3: All figures in $ thousands unless noted. Fiscal year ends December 31.
A6: PURPOSE
B7: A driver-based operating model for Chipotle built from the FY2025 Form 10-K. Revenue is
B8: forecast bottoms-up from restaurant units and average unit volume (AUV); costs are modeled
B9: as a percentage of revenue, consistent with how a restaurant FP&A team operates. The income
B10: statement, balance sheet, and cash flow statement are fully linked and self-balancing.
A12: TABS
A13: 1. Historicals | B13: Income statement (2023-25), balance sheet (2024-25), cash flow (2023-25) and key
B14: operating metrics, transcribed directly from the 10-K. Source notes in column to the right.
A15: 2. Assumptions | B15: All forecast drivers, with a Base / Bull / Bear scenario switch (yellow cell). Historical
B16: ratios are shown alongside each driver so every assumption is anchored to actual results.
A17: 3. Model | B17: The linked 3-statement forecast for 2026E-2027E next to 2023A-2025A actuals. Includes a
B18: balance-sheet check row that must equal zero in every column.
A19: 4. Variance | B19: Actual-vs-model backtest for FY2025 with a driver-based bridge decomposing the gap.
A20: 5. Dashboard | B20: A flat, tidy table of the key metrics by year, formatted for direct import into Power BI.
A22: HOW TO RUN SCENARIOS
B23: On the Assumptions tab, change the yellow scenario cell (1 = Base, 2 = Bull, 3 = Bear).
B24: Every driver and the entire model update automatically.
A26: COLOR KEY
A27: Blue | B27: Hardcoded input / assumption you can change
A28: Black | B28: Formula / calculation
A29: Green | B29: Link pulling from another tab
A31: KEY SIMPLIFYING ASSUMPTIONS (be ready to defend these)
B32: - Revenue = average units x revenue-per-average-unit; per-unit revenue grows at the comps rate.
B33: - Investments, goodwill, restricted cash, deferred tax and other long-term items held flat.
B34: Operating lease assets and liabilities held flat at 2025 levels (non-cash; rent is already in occupancy costs).
B35: - Share buybacks are an input; cash is the balancing plug (standard 3-statement convention).
B36: - Stock buybacks charged entirely to retained earnings (par effect immaterial, ~$0.6m in 2025).
A38: PRIMARY SOURCE | B38: Chipotle Mexican Grill, Inc. Form 10-K for FY ended Dec 31, 2025 (filed Feb 4, 2026).

Sheet Historicals 
A1: CHIPOTLE — HISTORICAL FINANCIALS ($000s) | B1: 2023A | C1: 2024A | D1: 2025A
A2: INCOME STATEMENT | E2: FY2025 10-K, Consolidated Statements of Income
A3: Food and beverage revenue | B3: 9804124 | C3: 11247384 | D3: 11866051
A4: Delivery service revenue | B4: 67525 | C4: 66469 | D4: 59550
A5: Total revenue | B5: =SUM(B3:B4) -> 9871649 | C5: =SUM(C3:C4) -> 11313853 | D5: =SUM(D3:D4) -> 11925601
A6: Food, beverage and packaging | B6: 2912564 | C6: 3374516 | D6: 3526992
A7: Labor | B7: 2440982 | C7: 2789789 | D7: 2991680
A8: Occupancy | B8: 503264 | C8: 563374 | D8: 624898
A9: Other operating costs | B9: 1428747 | C9: 1568482 | D9: 1755824
A10: General and administrative | B10: 633584 | C10: 697483 | D10: 652017
A11: Depreciation and amortization | B11: 319394 | C11: 335030 | D11: 361382
A12: Pre-opening costs | B12: 36931 | C12: 41897 | D12: 49507
A13: Impairment, closure costs, disposals | B13: 38370 | C13: 26949 | D13: 27503
A14: Total operating expenses | B14: 8313836 | C14: 9397520 | D14: 9989803
A15: Income from operations | B15: 1557813 | C15: 1916333 | D15: 1935798
A16: Interest and other income, net | B16: 62693 | C16: 93897 | D16: 73721
A17: Income before income taxes | B17: 1620506 | C17: 2010230 | D17: 2009519
... A20: Diluted weighted-avg shares | B20: 1385500 | C20: 1376555 | D20: 1342616
A22: BALANCE SHEET | C22: 2024A | D22: 2025A | E22: : FY2025 10-K, Consolidated Balance Sheets
A23: Cash and cash equivalents | C23: 748537 | D23: 350545
A24: Accounts receivable, net | C24: 143963 | D24: 156466
A25: Inventory | C25: 48942 | D25: 49508
A26: Prepaid expenses and other current | C26: 97538 | D26: 120450
A27: Income tax receivable | C27: 67229 | D27: 91393
A28: Investments (current) | C28: 674378 | D28: 698591
A29: Total current assets | C29: 1780587 | D29: 1466953
A30: Leasehold improv., property & equip., net | C30: 2390126 | D30: 2679361
A31: Long-term investments | C31: 868025 | D31: 197123
A32: Restricted cash | C32: 29842 | D32: 35364
A33: Operating lease assets | C33: 4000127 | D33: 4463010
A34: Other assets | C34: 113728 | D34: 130781
... A52: Total liabilities and equity | C52: 9204374 | D52: 8994531
A54: CASH FLOW (SELECTED) | B54: 2023A | C54: 2024A | D54: 2025A | E54: FY2025 10-K, Consolidated Statements of Cash Flows
A55: Net cash from operating activities | B55: 1783477 | C55: 2105076 | D55: 2113926
A56: Capital expenditures | B56: -560731 | C56: -593603 | D56: -666336
A57: Depreciation & amortization (CF) | B57: 319394 | C57: 335030 | D57: 361382
A58: Stock-based compensation (CF) | B58: 124016 | C58: 131730 | D58: 119543
A59: Repurchases of common stock (cash) | B59: -592349 | C59: -1001559 | D59: -2425516
A61: OPERATING METRICS | B61: 2023A | C61: 2024A | D61: 2025A | E61: FY2025 10-K, Item 7 (MD&A)
A62: Restaurants — beginning of year | C62: 3437 | D62: 3726
...

Sheet Assumptions
A1: CHIPOTLE — FORECAST ASSUMPTIONS
A2: Change the yellow cell to switch scenarios
A4: SCENARIO (1=Base, 2=Bull, 3=Bear) | B4: 1
A6: A. GROWTH DRIVERS (by year) | B6: 2026 Base | C6: 2026 Bull | D6: 2026 Bear | E6: 2026 ACTIVE | F6: 2027 Base | G6: 2027 Bull | H6: 2027 Bear | I6: 2027 ACTIVE | K6: Source / note
A7: New restaurant openings (gross) | B7: 345 | C7: 380 | D7: 300 | E7: =CHOOSE($B$4,B7,C7,D7) -> 345 | F7: 360 | G7: 400 | H7: 310 | I7: =CHOOSE($B$4,F7,G7,H7) -> 360 | K7: Feb 2026 guidance: 350-370 openings incl. 10-15 international partner-operated
A8: Permanent closures | B8: 13 | C8: 10 | D8: 20 | E8: =CHOOSE($B$4,B8,C8,D8) -> 13 | F8: 13 | G8: 10 | H8: 20 | I8: =CHOOSE($B$4,F8,G8,H8) -> 13
A9: Comparable / per-unit growth | B9: 0 | C9: 0.03 | D9: -0.03 | E9: =CHOOSE($B$4,B9,C9,D9) -> 0 | F9: 0.03 | G9: 0.05 | H9: 0 | I9: =CHOOSE($B$4,F9,G9,H9) -> 0.03 | K9: Feb 2026 guidance: 2026 comparable sales about flat
A11: B. MARGIN & POLICY DRIVERS | B11: Base | C11: Bull | D11: Bear | E11: ACTIVE
A12: Food, beverage & packaging % of revenue | B12: 0.297 | C12: 0.293 | D12: 0.303 | E12: =CHOOSE($B$4,B12,C12,D12) -> 0.297
A13: Labor % of revenue | B13: 0.252 | C13: 0.248 | D13: 0.258 | E13: =CHOOSE($B$4,B13,C13,D13) -> 0.252
A14: Occupancy % of revenue | B14: 0.053 | C14: 0.051 | D14: 0.056 | E14: =CHOOSE($B$4,B14,C14,D14) -> 0.053
A15: Other operating % of revenue | B15: 0.147 | C15: 0.143 | D15: 0.152 | E15: =CHOOSE($B$4,B15,C15,D15) -> 0.147
A16: G&A % of revenue | B16: 0.056 | C16: 0.053 | D16: 0.06 | E16: =CHOOSE($B$4,B16,C16,D16) -> 0.056
A17: D&A % of revenue | B17: 0.03 | C17: 0.03 | D17: 0.03 | E17: =CHOOSE($B$4,B17,C17,D17) -> 0.03
A18: Pre-opening cost per new restaurant ($000) | B18: 145 | C18: 140 | D18: 150 | E18: =CHOOSE($B$4,B18,C18,D18) -> 145
A19: Impairment & closure costs ($000) | B19: 28000 | C19: 24000 | D19: 34000 | E19: =CHOOSE($B$4,B19,C19,D19) -> 28000
A20: Interest/other income yield on cash+investments | B20: 0.035 | C20: 0.038 | D20: 0.03 | E20: =CHOOSE($B$4,B20,C20,D20) -> 0.035
A21: Effective tax rate | B21: 0.25 | C21: 0.248 | D21: 0.253 | E21: =CHOOSE($B$4,B21,C21,D21) -> 0.25 | K21: Base = midpoint of Feb 2026 guidance (24%-26% before discrete items)
A22: Capex per new restaurant ($000) | B22: 1500 | C22: 1500 | D22: 1550 | E22: =CHOOSE($B$4,B22,C22,D22) -> 1500
A23: Existing / corporate capex ($000) | B23: 290000 | C23: 300000 | D23: 270000 | E23: =CHOOSE($B$4,B23,C23,D23) -> 290000
A24: Share repurchases ($000) | B24: 1300000 | C24: 1500000 | D24: 1000000 | E24: =CHOOSE($B$4,B24,C24,D24) -> 1300000

Sheet Model
A1: CHIPOTLE — 3-STATEMENT OPERATING MODEL ($000s)
C3: 2023A | D3: 2024A | E3: 2025A | F3: 2026E | G3: 2027E
A5: UNIT & REVENUE BUILD
A6: Restaurants — beginning of year | D6: ='Historicals '!C62 -> 3437 | E6: ='Historicals '!D62 -> 3726 | F6: =E9 -> 4042 | G6: =F9 -> 4374
A7: New openings (gross) | D7: ='Historicals '!C63 -> 304 | E7: ='Historicals '!D63 -> 334 | F7: =Assumptions!E7 -> 345 | G7: =Assumptions!I7 -> 360
A8: Closures & relocations | D8: ='Historicals '!C64 -> -15 | E8: ='Historicals '!D64 -> -18 | F8: =-Assumptions!E8 -> -13 | G8: =-Assumptions!I8 -> -13
A9: Restaurants — end of year | C9: ='Historicals '!B65 -> 3437 | D9: =D6+D7+D8 -> 3726 | E9: =E6+E7+E8 -> 4042 | F9: =F6+F7+F8 -> 4374 | G9: =G6+G7+G8 -> 4721
A10: Average restaurants | D10: =AVERAGE(C9,D9) -> 3581.5 | E10: =AVERAGE(D9,E9) -> 3884 | F10: =AVERAGE(E9,F9) -> 4208 | G10: =AVERAGE(F9,G9) -> 4547.5
A11: Revenue per avg restaurant ($000) | D11: ='Historicals '!C5/D10 -> 3158.9705 | E11: ='Historicals '!D5/E10 -> 3070.4431 | F11: =E11*(1+F12) -> 3070.4431 | G11: =F11*(1+G12) -> 3162.5564
A12: Comparable / per-unit growth | C12: ='Historicals '!B67 -> 0.079 | D12: ='Historicals '!C67 -> 0.074 | E12: ='Historicals '!D67 -> -0.017 | F12: =Assumptions!E9 -> 0 | G12: =Assumptions!I9 -> 0.03
A13: Total revenue ($000) | C13: ='Historicals '!B5 -> 9871649 | D13: ='Historicals '!C5 -> 11313853 | E13: ='Historicals '!D5 -> 11925601 | F13: =F10*F11 -> 12920425 | G13: =G10*G11 -> 14381725
A14: Income Statement
A15: Food, beverage & packaging | C15: ='Historicals '!B6 -> 2912564 | D15: ='Historicals '!C6 -> 3374516 | E15: ='Historicals '!D6 -> 3526992 | F15: =F$13*Assumptions!$E$12 -> 3837366.1 | G15: =G$13*Assumptions!$E$12 -> 4271372.4
A16: Labour | C16: ='Historicals '!B7 -> 2440982 | D16: ='Historicals '!C7 -> 2789789 | E16: ='Historicals '!D7 -> 2991680 | F16: =F$13*Assumptions!$E$13 -> 3255947 | G16: =G$13*Assumptions!$E$13 -> 3624194.7
A17: Occupancy | C17: ='Historicals '!B8 -> 503264 | D17: ='Historicals '!C8 -> 563374 | E17: ='Historicals '!D8 -> 624898 | F17: =F$13*Assumptions!$E$14 -> 684782.5 | G17: =G$13*Assumptions!$E$14 -> 762231.44
A18: Other operating costs | C18: ='Historicals '!B9 -> 1428747 | D18: ='Historicals '!C9 -> 1568482 | E18: ='Historicals '!D9 -> 1755824 | F18: =F$13*Assumptions!$E$15 -> 1899302.4 | G18: =G$13*Assumptions!$E$15 -> 2114113.6
A19: G&A | C19: ='Historicals '!B10 -> 633584 | D19: ='Historicals '!C10 -> 697483 | E19: ='Historicals '!D10 -> 652017 | F19: =F$13*Assumptions!$E$16 -> 723543.78 | G19: =G$13*Assumptions!$E$16 -> 805376.61
A20: D&A | C20: ='Historicals '!B11 -> 319394 | D20: ='Historicals '!C11 -> 335030 | E20: ='Historicals '!D11 -> 361382 | F20: =F$13*Assumptions!$E$17 -> 387612.74 | G20: =G$13*Assumptions!$E$17 -> 431451.76
A21: Pre opening | C21: ='Historicals '!B12 -> 36931 | D21: ='Historicals '!C12 -> 41897 | E21: ='Historicals '!D12 -> 49507 | F21: =F$7*Assumptions!$E$18 -> 50025 | G21: =G$7*Assumptions!$E$18 -> 52200
A22: Impairment, closure costs, disposals | C22: ='Historicals '!B13 -> 38370 | D22: ='Historicals '!C13 -> 26949 | E22: ='Historicals '!D13 -> 27503 | F22: =Assumptions!$E$19 -> 28000 | G22: =Assumptions!$E$19 -> 28000
A23: Total operating expenses | C23: =SUM(C15:C22) -> 8313836 | D23: =SUM(D15:D22) -> 9397520 | E23: =SUM(E15:E22) -> 9989803 | F23: =SUM(F15:F22) -> 10866580 | G23: =SUM(G15:G22) -> 12088941
A24: Income from operations | C24: =C13-C23 -> 1557813 | D24: =D13-D23 -> 1916333 | E24: =E13-E23 -> 1935798 | F24: =F13-F23 -> 2053845.1 | G24: =G13-G23 -> 2292784.7
A25: Interest and other income, net | C25: ='Historicals '!B16 -> 62693 | D25: ='Historicals '!C16 -> 93897 | E25: ='Historicals '!D16 -> 73721 | F25: =Assumptions!$E$20*(E57+E62+E65) -> 43619.065 | G25: =Assumptions!$E$20*(F57+F62+F65) -> 44298.532
A26: Income before income taxes | C26: =C24+C25 -> 1620506 | D26: =D24+D25 -> 2010230 | E26: =E24+E25 -> 2009519 | F26: =F24+F25 -> 2097464.1 | G26: =G24+G25 -> 2337083.2
A27: Provision for income taxes | C27: ='Historicals '!B18 -> 391769 | D27: ='Historicals '!C18 -> 476120 | E27: ='Historicals '!D18 -> 473758 | F27: =F26*Assumptions!$E$21 -> 524366.03 | G27: =G26*Assumptions!$E$21 -> 584270.8
A28: Net Income | C28: =C26-C27 -> 1228737 | D28: =D26-D27 -> 1534110 | E28: =E26-E27 -> 1535761 | F28: =F26-F27 -> 1573098.1 | G28: =G26-G27 -> 1752812.4
A30: CASH FLOW STATEMENT
A31: Net income | C31: =C28 -> 1228737 | D31: =D28 -> 1534110 | E31: =E28 -> 1535761 | F31: =F28 -> 1573098.1 | G31: =G28 -> 1752812.4
A32: Depreciation & amortization | C32: ='Historicals '!B57 -> 319394 | D32: ='Historicals '!C57 -> 335030 | E32: ='Historicals '!D57 -> 361382 | F32: =F20 -> 387612.74 | G32: =G20 -> 431451.76
A33: Stock-based compensation | C33: ='Historicals '!B58 -> 124016 | D33: ='Historicals '!C58 -> 131730 | E33: ='Historicals '!D58 -> 119543 | F33: =E33 -> 119543 | G33: =E33 -> 119543
A34: Changes in working capital:
A35: Accounts receivable | F35: =-(F58-E58) -> -13052.262 | G35: =-(G58-F58) -> -19172.523
A36: Inventory | F36: =-(F59-E59) -> -4129.9156 | G36: =-(G59-F59) -> -6066.4508
A37: Prepaid & other current | F37: =-(F60-E60) -> -10047.837 | G37: =-(G60-F60) -> -14759.312
A38: Income tax receivable | F38: =-(F61-E61) -> 0 | G38: =-(G61-F61) -> 0
A39: Accounts payable | F39: =F72-E72 -> 17752.681 | G39: =G72-F72 -> 26076.989
A40: Accrued payroll | F40: =F73-E73 -> 20865.3 | G40: =G73-F73 -> 30649.129
A41: Accrued liabilities | F41: =F74-E74 -> 15219.658 | G41: =G74-F74 -> 22356.222
A42: Unearned revenue | F42: =F75-E75 -> 20051.88 | G42: =G75-F75 -> 29454.292
A43: Other (net)
...

Sheet Dashboard
A1: Year | B1: Period | C1: Metric | D1: Category | E1: Value
A2: 2023 | B2: Actual | C2: Net income | D2: Income | E2: =Model!C28 -> 1228737
A3: 2024 | B3: Actual | C3: Net income | D3: Income | E3: =Model!D28 -> 1534110
A4: 2025 | B4: Actual | C4: Net income | D4: Income | E4: =Model!E28 -> 1535761
A5: 2026 | B5: Forecast | C5: Net income | D5: Income | E5: =Model!F28 -> 1573098.1
A6: 2027 | B6: Forecast | C6: Net income | D6: Income | E6: =Model!G28 -> 1752812.4
A7: 2023 | B7: Actual | C7: Operating income | D7: Income | E7: =Model!C24 -> 1557813
A8: 2024 | B8: Actual | C8: Operating income | D8: Income | E8: =Model!D24 -> 1916333
A9: 2025 | B9: Actual | C9: Operating income | D9: Income | E9: =Model!E24 -> 1935798
A10: 2026 | B10: Forecast | C10: Operating income | D10: Income | E10: =Model!F24 -> 2053845.1
A11: 2027 | B11: Forecast | C11: Operating income | D11: Income | E11: =Model!G24 -> 2292784.7
A12: 2023 | B12: Actual | C12: Cash from operations | D12: Cashflow | E12: =Model!C44 -> 1783477
A13: 2024 | B13: Actual | C13: Cash from operations | D13: Cashflow | E13: =Model!D44 -> 2105076
A14: 2025 | B14: Actual | C14: Cash from operations | D14: Cashflow | E14: =Model!E44 -> 2113926
A15: 2026 | B15: Forecast | C15: Cash from operations | D15: Cashflow | E15: =Model!F44 -> 2126913.3
A16: 2027 | B16: Forecast | C16: Cash from operations | D16: Cashflow | E16: =Model!G44 -> 2372345.5
A17: 2023 | B17: Actual | C17: Capex | D17: Cashflow | E17: =-Model!C46 -> 560731
A18: 2024 | B18: Actual | C18: Capex | D18: Cashflow | E18: =-Model!D46 -> 593603
A19: 2025 | B19: Actual | C19: Capex | D19: Cashflow | E19: =-Model!E46 -> 666336
A20: 2026 | B20: Forecast | C20: Capex | D20: Cashflow | E20: =-Model!F46 -> 807500
A21: 2027 | B21: Forecast | C21: Capex | D21: Cashflow | E21: =-Model!G46 -> 830000
A22: 2023 | B22: Actual | C22: Free cash flow | D22: Cashflow | E22: =Model!C44+Model!C46 -> 1222746
A23: 2024 | B23: Actual | C23: Free cash flow | D23: Cashflow | E23: =Model!D44+Model!D46 -> 1511473
A24: 2025 | B24: Actual | C24: Free cash flow | D24: Cashflow | E24: =Model!E44+Model!E46 -> 1447590
A25: 2026 | B25: Forecast | C25: Free cash flow | D25: Cashflow | E25: =Model!F44+Model!F46 -> 1319413.3
A26: 2027 | B26: Forecast | C26: Free cash flow | D26: Cashflow | E26: =Model!G44+Model!G46 -> 1542345.5
A27: 2023 | B27: Actual | C27: Ending cash | D27: Balance
A28: 2024 | B28: Actual | C28: Ending cash | D28: Balance | E28: =Model!D57 -> 748537
A29: 2025 | B29: Actual | C29: Ending cash | D29: Balance | E29: =Model!E57 -> 350545
A30: 2026 | B30: Forecast | C30: Ending cash | D30: Balance | E30: =Model!F57 -> 369958.33
A31: 2027 | B31: Forecast | C31: Ending cash | D31: Balance | E31: =Model!G57 -> 612303.82
A32: 2023 | B32: Actual | C32: Total assets | D32: Balance
A33: 2024 | B33: Actual | C33: Total assets | D33: Balance | E33: =Model!D70 -> 9204374
A34: 2025 | B34: Actual | C34: Total assets | D34: Balance | E34: =Model!E70 -> 8994531
A35: 2026 | B35: Forecast | C35: Total assets | D35: Balance | E35: =Model!F70 -> 9461061.6
A36: 2027 | B36: Forecast | C36: Total assets | D36: Balance | E36: =Model!G70 -> 10141954
A37: 2023 | B37: Actual | C37: Restaurants | D37: KPI | E37: =Model!C9 -> 3437
A38: 2024 | B38: Actual | C38: Restaurants | D38: KPI | E38: =Model!D9 -> 3726
A39: 2025 | B39: Actual | C39: Restaurants | D39: KPI | E39: =Model!E9 -> 4042
A40: 2026 | B40: Forecast | C40: Restaurants | D40: KPI | E40: =Model!F9 -> 4374
...

Sheet Variance
A1: CHIPOTLE — FY2025 VARIANCE ANALYSIS ($000s)
A2: Budget anchored to management guidance from Q4'24 earnings call (Feb 2025)
B3: FY2025 Budget | C3: FY2025 Actual | D3: Variance $ | E3: Variance %
A4: DRIVERS
A5: New restaurant openings (gross) | B5: 330 | C5: ='Historicals '!D63 -> 334 | D5: =C5-B5 -> 4 | E5: =D5/B5 -> 0.012121212
A6: Permanent closures | B6: 18 | C6: =-'Historicals '!D64 -> 18 | D6: =C6-B6 -> 0
A7: Comparable sales growth | B7: 0.04 | C7: ='Historicals '!D67 -> -0.017 | D7: =C7-B7 -> -0.057
A8: Average restaurants | B8: =('Historicals '!D62+('Historicals '!D62+B5-B6))/2 -> 3882 | C8: =Model!E10 -> 3884 | D8: =C8-B8 -> 2 | E8: =D8/B8 -> 0.00051519835
A9: Revenue per avg restaurant ($000) | B9: =Model!D11*(1+B7) -> 3285.3294 | C9: =Model!E11 -> 3070.4431 | D9: =C9-B9 -> -214.88626 | E9: =D9/B9 -> -0.06540783
A10: Budget operating margin (assumption) | B10: 0.165
A11: INCOME STATEMENT ($000)
A12: Total revenue | B12: =B8*B9 -> 12753649 | C12: ='Historicals '!D5 -> 11925601 | D12: =C12-B12 -> -828047.59 | E12: =D12/B12 -> -0.06492633
A13: Total operating expenses | B13: =B12*(1-B10) -> 10649297 | C13: ='Historicals '!D14 -> 9989803 | D13: =C13-B13 -> -659493.58 | E13: =D13/B13 -> -0.06192837
A14: Income from operations | B14: =B12-B13 -> 2104352 | C14: ='Historicals '!D15 -> 1935798 | D14: =C14-B14 -> -168554.02 | E14: =D14/B14 -> -0.080097824
A15: Operating margin % | B15: =B14/B12 -> 0.165 | C15: =C14/C12 -> 0.16232289 | D15: =C15-B15 -> -0.0026771116
A16: Interest and other income | B16: 65000 | C16: ='Historicals '!D16 -> 73721 | D16: =C16-B16 -> 8721 | E16: =D16/B16 -> 0.13416923
A17: Income before income taxes | B17: =B14+B16 -> 2169352 | C17: ='Historicals '!D17 -> 2009519 | D17: =C17-B17 -> -159833.02 | E17: =D17/B17 -> -0.07367777
A18: Effective tax rate % | B18: 0.26 | C18: =C19/C17 -> 0.23575691 | D18: =C18-B18 -> -0.024243085 | G18: Budget = midpoint of Feb 2025 guidance (25%-27%)
A19: Provision for income taxes | B19: =B17*B18 -> 564031.52 | C19: ='Historicals '!D18 -> 473758 | D19: =C19-B19 -> -90273.525 | E19: =D19/B19 -> -0.16005049
A20: Net income | B20: =B17-B19 -> 1605320.5 | C20: ='Historicals '!D19 -> 1535761 | D20: =C20-B20 -> -69559.493 | E20: =D20/B20 -> -0.043330596
A21: Net income margin % | B21: =B20/B12 -> 0.12587147 | C21: =C20/C12 -> 0.1287785 | D21: =C21-B21 -> 0.0029070295
A23: REVENUE BRIDGE — VOLUME vs RATE
A24: Budgeted revenue | B24: =B12 -> 12753649
A25: (+) Volume effect | B25: =(C8-B8)*B9 -> 6570.6587
A26: (+) Rate effect | B26: =(C9-B9)*C8 -> -834618.25 | D26: Comps | E26: =Model!D11*(C7-B7)*C8 -> -699358.17
A27: Actual revenue | B27: =B24+B25+B26 -> 11925601 | D27: Non Comps | E27: =B26-E26 -> -135260.08
A29: Volume % of total variance | B29: =B25/(B25+B26) -> -0.0079351221
A30: Rate % of total variance | B30: =B26/(B25+B26) -> 1.0079351
A32: Commentary
